Workbook
Name \0: #N/A
Name \A: [1]Laba!#REF!
Name \B: [1]Laba!#REF!
Name \C: [1]Laba!#REF!
Name \D: [2]Sheet1!$CO$8
Name \E: [2]Sheet1!$CO$10
Name \F: [2]Sheet1!$CO$12
Name \G: [2]Sheet1!$CO$14
Name \GD: #N/A
Name \H: [2]Sheet1!$CO$16
Name \I: [2]Sheet1!$CO$18
Name \J: [2]Sheet1!$CO$20
Name \K: [2]Sheet1!$CO$22
Name \L: [2]Sheet1!$CO$24
Name \m: #N/A
Name \n: #N/A
Name \o: #N/A
Name \p: #N/A
Name \q: #N/A
Name \r: #N/A
Name \s: #N/A
Name \t: #N/A
Name \u: #N/A
Name \v: #N/A
Name \w: #N/A
Name \x: #N/A
Name \y: #N/A
Name \z: #N/A
Name _\0: #N/A
Name _\GD: #N/A
Name _\o: #N/A
Name _\p: #N/A
Name _\q: #N/A
Name _\R: #N/A
Name _\s: #N/A
Name _\t: #N/A
Name _\u: #N/A
Name _\v: #N/A
Name _\w: #N/A
Name _\x: #N/A
Name _\y: #N/A
Name _\z: #N/A
Name _____________________HAL2: #REF!
Name _________________HAL2: #REF!
Name ________________HAL1: #N/A
Name _______________mpp1102: [3]MPP0102!$A$1:$AJ$1973
Name ______________HAL1: #N/A
Name ______________HAL2: #REF!
Name ______________mpp1102: [4]MPP0102!$A$1:$AJ$1973
Name _____________HAL1: #N/A
Name _____________mpp1002: [3]MPP0102!$A$1:$AJ$1973
Name _____________mpp1102: [4]MPP0102!$A$1:$AJ$1973
Name ____________HAL1: #N/A
Name ____________HAL2: #REF!
Name ____________mpp1002: [4]MPP0102!$A$1:$AJ$1973
Name ____________mpp1102: [4]MPP0102!$A$1:$AJ$1973
Name ___________HAL1: #N/A
Name ___________HAL2: #REF!
Name ___________mpp1002: [4]MPP0102!$A$1:$AJ$1973
Name ___________mpp1102: [5]MPP0102!$A$1:$AJ$1973

Sheet Input - OD Intl
C2: Jenis Produk (In Bulk / In Bag) | D2: Info Tarif Angkutan Bulan Mei 2023
D3: Tujuan | F3: Asal | K3: Term and Condition
F4: PKG | G4: PKC | H4: PKT | I4: PIM | J4: PSP
D5: Negara | E5: Pelabuhan | F5: Gresik | G5: Cigading | H5: Bontang | I5: Lhoksumawe | J5: Palembang
C6: Urea | D6: Philippine | E6: Davao | F6: 1207 | G6: 1561 | H6: 697 | I6: 1539 | J6: 1672
D7: Thailand | E7: Bangkok | F7: 1479 | G7: 1303 | H7: 1751 | I7: 1321 | J7: 1074
D8: Vietnam | E8: Hai Phong | F8: 1820 | G8: 1684 | H8: 1577 | I8: 1790 | J8: 1510
D9: Jepang | E9: Nagoya | F9: 2995 | G9: 3084 | H9: 2485 | I9: 3265 | J9: 2961
D10: Taiwan | E10: Taichung | F10: 2059 | G10: 2061 | H10: 1539 | I10: 2188 | J10: 1891
D11: WC-India | E11: Mundra | F11: 3414 | G11: 2983 | H11: 3906 | I11: 2277 | J11: 3024
D12: Australia | E12: Geelong | F12: 3242 | G12: 3329 | H12: 3627 | I12: 4328 | J12: 3640
D13: North Afrika | E13: Jorf Lasfar | F13: 7821 | G13: 7390 | H13: 8314 | I13: 6697 | J13: 7443
D14: Brazil | E14: Santos | F14: 8825 | G14: 8394 | H14: 9154 | I14: 8494 | J14: 8705
C15: NPK | D15: Philippine | E15: Davao | F15: 1207 | G15: 1561 | H15: 697 | I15: 1539 | J15: 1672
D16: Thailand | E16: Bangkok | F16: 1479 | G16: 1303 | H16: 1751 | I16: 1321 | J16: 1074
D17: Vietnam | E17: Hai Phong | F17: 1820 | G17: 1684 | H17: 1577 | I17: 1790 | J17: 1510
D18: Malaysia | E18: Port Klang | F18: 957 | G18: 746 | H18: 1339 | I18: 303 | J18: 466
D19: Laos
D20: WC-India | E20: Mundra | F20: 3414 | G20: 2983 | H20: 3906 | I20: 2277 | J20: 3024
D21: Morocco | E21: Jorf Lasfar | F21: 7821 | G21: 7390 | H21: 8314 | I21: 6697 | J21: 7443
D22: Myanmar | E22: Yangon | F22: 1853 | G22: 1641 | H22: 2234 | I22: 698 | J22: 1361
D23: Afsel | E23: Richard's Bay | F23: 4815 | G23: 4384 | H23: 5308 | I23: 4332 | J23: 4695
D24: Mesir | E24: Port Said | F24: 5665 | G24: 5234 | H24: 6158 | I24: 4541 | J24: 5287
D25: Tanzania | E25: Dar es Salaam | F25: 4413 | G25: 3982 | H25: 4905 | I25: 3562 | J25: 4292
D26: Ghana | E26: Tema | F26: 8140 | G26: 7709 | H26: 8632 | I26: 7728 | J26: 8019
C27: Amoniak | D27: Jepang | E27: Niihama | F27: 2918 | G27: 2944 | H27: 2408 | I27: 3131 | J27: 2818
D28: South Korea | E28: Busan | F28: 2809 | G28: 2849 | H28: 2289 | I28: 2975 | J28: 2679
D29: China | E29: Zhoushan | F29: 2415 | G29: 2410 | H29: 1895 | I29: 2535 | J29: 2241
D30: Australia | E30: Kwinana | F30: 1630 | G30: 1722 | H30: 2015 | I30: 2747 | J30: 2033
D31: WC-India | E31: Tuticorin | F31: 2363 | G31: 1932 | H31: 2855 | I31: 1226 | J31: 1973
D32: Myanmar | E32: Yangon | F32: 1853 | G32: 1641 | H32: 2234 | I32: 698 | J32: 1361
D33: Thailand | E33: Bangkok | F33: 1479 | G33: 1303 | H33: 1751 | I33: 1321 | J33: 1074
D34: Taiwan | E34: Taichung | F34: 2059 | G34: 2061 | H34: 1153 | I34: 2188 | J34: 1891

Sheet Input - Bunker
A1: Bunker Port | B1: VLSFO | C1: HSD | D1: Date
A2: Singapore | B2: 504 | C2: 591 | D2: 45786
B4: Clarkson Shipping Intelligence Weekly 09/05/25

Sheet Input - Vessel List
A1: No | B1: Nama Kapal | C1: TCE Rate | D1: DWT (MT) | E1: GT (MT) | F1: Draft (M) | G1: Speed Max (Knot) | H1: Speed Average (Knot) | I1: ME Fuel Type | J1: ME Power | K1: AE Power | L1: ME Cons | M1: AE Cons | N1: Tahun Pembuatan | O1: Jenis Kapal | P1: Flag | Q1: Status
A2: 1 | B2: Handysize | C2: 12000 | E2: 7497 | F2: 7.2 | G2: 12 | H2: 10 | I2: HSD | J2: =2*2500 -> 5000 | K2: =420 -> 420 | L2: =J2*0.7*0.12*24/0.86/1000 -> 11.72093 | M2: =K2*0.7*0.12*24/0.86/1000 -> 0.98455814 | N2: 1984 | O2: Dry bulk | P2: Indonesia | Q2: Owned
A3: 2 | B3: Handy SR | C3: 25809 | D3: 9327.4 | E3: 7451 | F3: 7.2 | G3: 12 | H3: 10 | I3: HSD | J3: =2*2500 -> 5000 | K3: =650 -> 650 | L3: =J3*0.7*0.12*24/0.86/1000 -> 11.72093 | M3: =K3*0.7*0.12*24/0.86/1000 -> 1.5237209 | N3: 1977 | O3: Dry bulk | P3: Indonesia | Q3: Owned
A4: 3 | B4: KM Soemantri Brodjonegoro | D4: 11161.5 | E4: 7473 | F4: 7.2 | G4: 8 | H4: 7 | I4: HSD | J4: =2*2500 -> 5000 | K4: =650 -> 650 | L4: =J4*0.7*0.12*24/0.86/1000 -> 11.72093 | M4: =K4*0.7*0.12*24/0.86/1000 -> 1.5237209 | N4: 1977 | O4: Dry bulk | P4: Indonesia | Q4: Owned
A5: 4 | B5: KM Julianto Moeliodihardjo | D5: 11161.5 | E5: 7473 | F5: 7.2 | G5: 7 | H5: 6.5 | I5: HSD | J5: =2*2500 -> 5000 | K5: =420 -> 420 | L5: =J5*0.7*0.12*24/0.86/1000 -> 11.72093 | M5: =K5*0.7*0.12*24/0.86/1000 -> 0.98455814 | N5: 1983 | O5: Dry bulk | P5: Indonesia | Q5: Owned
A6: 5 | B6: KM Pusri Indonesia | D6: 11195.4 | E6: 7339 | F6: 7.2 | G6: 8 | H6: 7 | I6: HSD | J6: =2*2500 -> 5000 | K6: =650 -> 650 | L6: =J6*0.7*0.12*24/0.86/1000 -> 11.72093 | M6: =K6*0.7*0.12*24/0.86/1000 -> 1.5237209 | N6: 1978 | O6: Dry bulk | P6: Indonesia | Q6: Owned
A7: 6 | B7: KM Mochtar Prabu Mangkunegara | D7: 11185.4 | E7: 7497 | F7: 7.2 | G7: 8 | H7: 7 | I7: HSD | J7: =2*2500 -> 5000 | K7: =420 -> 420 | L7: =J7*0.7*0.12*24/0.86/1000 -> 11.72093 | M7: =K7*0.7*0.12*24/0.86/1000 -> 0.98455814 | N7: 1983 | O7: Dry bulk | P7: Indonesia | Q7: Owned
A8: 7 | B8: KM Pusri Indonesia 1 | D8: 11485 | E8: 12454 | F8: 5.4 | G8: 8 | H8: 7 | I8: HSD | J8: =2*2100 -> 4200 | K8: =480 -> 480 | L8: =J8*0.7*0.12*24/0.86/1000 -> 9.8455814 | M8: =K8*0.7*0.12*24/0.86/1000 -> 1.1252093 | N8: 2014 | O8: General Cargo | P8: Indonesia | Q8: Owned
A9: 8 | B9: MT Sultan Mahmud Badaruddin II | D9: 11485 | E9: 7305 | F9: 6.2 | G9: 10 | H9: 10 | I9: HSD | J9: 5200 | K9: =650 -> 650 | L9: =J9*0.7*0.12*24/0.86/1000 -> 12.189767 | M9: =K9*0.7*0.12*24/0.86/1000 -> 1.5237209 | N9: 1984 | O9: LPG/C | P9: Indonesia | Q9: Owned
A10: 9 | B10: MT Salmon Mustafa | D10: 23256 | E10: 19511 | F10: 14.39 | G10: 10 | H10: 10 | I10: HSD | J10: 18200 | K10: =650 -> 650 | L10: =J10*0.7*0.12*24/0.86/1000 -> 42.664186 | M10: =K10*0.7*0.12*24/0.86/1000 -> 1.5237209 | N10: 1994 | O10: LPG/C | P10: Indonesia | Q10: Owned
D43: update 28/02/2025

Sheet Input - Time Sheet
A1: Vessel Name | B1: Voyage | C1: Activity | D1: Time Start | E1: Time Stop | F1: Duration
A2: KM Julianto Moeliodihardjo | B2: 1 | C2: Waiting Loading | D2: 45083.25 | E2: 45087.25 | F2: =E2-D2 -> 4
A3: KM Julianto Moeliodihardjo | B3: 1 | C3: Loading | D3: 45087.25 | E3: 45091.25 | F3: =E3-D3 -> 4
A4: KM Julianto Moeliodihardjo | B4: 1 | C4: Sailing to PoD | D4: 45091.25 | E4: 45098.25 | F4: =E4-D4 -> 7
A5: KM Julianto Moeliodihardjo | B5: 1 | C5: Waiting Discharge | D5: 45098.25 | E5: 45099.25 | F5: =E5-D5 -> 1
A6: KM Julianto Moeliodihardjo | B6: 1 | C6: Discharge | D6: 45099.25 | E6: 45102.25 | F6: =E6-D6 -> 3

Sheet Process - Intl
A1: No | B1: Ship class | C1: Loading Port | D1: Country | E1: Discharge Port | F1: COB | G1: Loading rate | H1: Discharge rate | I1: Free Time at PoL | J1: Free Time at PoD | K1: ME Fuel Type | L1: ME Fuel price | M1: Bunker Port | N1: VLSFO Price | O1: HSD Price | P1: Distance | Q1: Service speed | R1: Sailing Days | S1: Port Days | T1: Waiting Days | U1: Total Days | V1: ME Fuel Cons | W1: AE Fuel Cons | X1: Bunker Sailing | Y1: Bunker at Port | Z1: Bunker Waiting | AA1: Total Bunker | AB1: Port Charges | AC1: Canal Dues | AD1: TCE Rate | AE1: Total Fixed cost | AF1: Total Cost | AG1: Freight
A2: 1 | B2: Handysize | C2: Gresik | D2: Philippines | E2: Davao | F2: 30000 | G2: 4000 | H2: 4000 | I2: 1 | J2: 0 | K2: VLSFO | L2: =IF(K2 ="VLSFO", $N$2,$O$2) -> 504 | M2: Singapore | N2: =VLOOKUP(M2, 'Input - Bunker'!$A$2:$C$5,2,0) -> 504 | O2: =VLOOKUP(M2, 'Input - Bunker'!$A$2:$C$5,3,0) -> 591 | P2: ='Input - OD Intl'!F6 -> 1207 | Q2: =VLOOKUP(B2, 'Input - Vessel List'!$B$2:$K$11, 7,0) -> 10 | R2: =P2*2/(Q2*24) -> 10.058333 | S2: =(F2/G2)+(F2/H2) -> 15 | T2: =I2+J2 -> 1 | U2: =SUM(R2:T2) -> 26.058333 | V2: =VLOOKUP(B2, 'Input - Vessel List'!$B$2:$M$15, 11,0) -> 11.72093 | W2: =VLOOKUP(B2, 'Input - Vessel List'!$B$2:$M$15, 12,0) -> 0.98455814 | X2: =((R2*L2*V2)+(R2*L2*W2))*-1 -> -64409.203 | Y2: =S2*O2*W2*2*-1 -> -17456.216 | Z2: =T2*O2*W2*-1 -> -581.87386 | AA2: =SUM(X2:Z2) -> -82447.292 | AB2: =2.05*F2*-1*2 -> -123000 | AD2: =VLOOKUP(B2,'Input - Vessel List'!B:C,2,0) -> 12000 | AE2: =AD2*U2*-1 -> -312700 | AF2: =AA2+AB2+AE2+AC2 -> -518147.29 | AG2: =AF2/F2*-1 -> 17.271576
A3: 2 | B3: Handysize | C3: Gresik | D3: Thailand | E3: Bangkok | F3: 30000 | G3: 4000 | H3: =200*20 -> 4000 | I3: 1 | J3: 0 | K3: VLSFO | L3: =IF(K3 ="VLSFO", $N$2,$O$2) -> 504 | M3: Singapore | N3: =VLOOKUP(M3, 'Input - Bunker'!$A$2:$C$5,2,0) -> 504 | O3: =VLOOKUP(M3, 'Input - Bunker'!$A$2:$C$5,3,0) -> 591 | P3: ='Input - OD Intl'!F7 -> 1479 | Q3: =VLOOKUP(B3, 'Input - Vessel List'!$B$2:$K$11, 7,0) -> 10 | R3: =P3*2/(Q3*24) -> 12.325 | S3: =(F3/G3)+(F3/H3) -> 15 | T3: =I3+J3 -> 1 | U3: =SUM(R3:T3) -> 28.325 | V3: =VLOOKUP(B3, 'Input - Vessel List'!$B$2:$M$15, 11,0) -> 11.72093 | W3: =VLOOKUP(B3, 'Input - Vessel List'!$B$2:$M$15, 12,0) -> 0.98455814 | X3: =((R3*L3*V3)+(R3*L3*W3))*-1 -> -78923.953 | Y3: =S3*O3*W3*2*-1 -> -17456.216 | Z3: =T3*O3*W3*-1 -> -581.87386 | AA3: =SUM(X3:Z3) -> -96962.042 | AB3: =2.05*F3*-1*2 -> -123000 | AD3: =VLOOKUP(B3,'Input - Vessel List'!B:C,2,0) -> 12000 | AE3: =AD3*U3*-1 -> -339900 | AF3: =AA3+AB3+AE3+AC3 -> -559862.04 | AG3: =AF3/F3*-1 -> 18.662068
A4: 3 | B4: Handysize | C4: Gresik | D4: Vietnam | E4: Hai Phong | F4: 30000 | G4: 4000 | H4: =200*20 -> 4000 | I4: 1 | J4: 0 | K4: VLSFO | L4: =IF(K4 ="VLSFO", $N$2,$O$2) -> 504 | M4: Singapore | N4: =VLOOKUP(M4, 'Input - Bunker'!$A$2:$C$5,2,0) -> 504 | O4: =VLOOKUP(M4, 'Input - Bunker'!$A$2:$C$5,3,0) -> 591 | P4: ='Input - OD Intl'!F8 -> 1820 | Q4: =VLOOKUP(B4, 'Input - Vessel List'!$B$2:$K$11, 7,0) -> 10 | R4: =P4*2/(Q4*24) -> 15.166667 | S4: =(F4/G4)+(F4/H4) -> 15 | T4: =I4+J4 -> 1 | U4: =SUM(R4:T4) -> 31.166667 | V4: =VLOOKUP(B4, 'Input - Vessel List'!$B$2:$M$15, 11,0) -> 11.72093 | W4: =VLOOKUP(B4, 'Input - Vessel List'!$B$2:$M$15, 12,0) -> 0.98455814 | X4: =((R4*L4*V4)+(R4*L4*W4))*-1 -> -97120.753 | Y4: =S4*O4*W4*2*-1 -> -17456.216 | Z4: =T4*O4*W4*-1 -> -581.87386 | AA4: =SUM(X4:Z4) -> -115158.84 | AB4: =2.05*F4*-1*2 -> -123000 | AD4: =VLOOKUP(B4,'Input - Vessel List'!B:C,2,0) -> 12000 | AE4: =AD4*U4*-1 -> -374000 | AF4: =AA4+AB4+AE4+AC4 -> -612158.84 | AG4: =AF4/F4*-1 -> 20.405295
A5: 4 | B5: Handysize | C5: Gresik | D5: Jepang | E5: Nagoya | F5: 30000 | G5: 4000 | H5: =200*20 -> 4000 | I5: 1 | J5: 0 | K5: VLSFO | L5: =IF(K5 ="VLSFO", $N$2,$O$2) -> 504 | M5: Singapore | N5: =VLOOKUP(M5, 'Input - Bunker'!$A$2:$C$5,2,0) -> 504 | O5: =VLOOKUP(M5, 'Input - Bunker'!$A$2:$C$5,3,0) -> 591 | P5: ='Input - OD Intl'!F9 -> 2995 | Q5: =VLOOKUP(B5, 'Input - Vessel List'!$B$2:$K$11, 7,0) -> 10 | R5: =P5*2/(Q5*24) -> 24.958333 | S5: =(F5/G5)+(F5/H5) -> 15 | T5: =I5+J5 -> 1 | U5: =SUM(R5:T5) -> 40.958333 | V5: =VLOOKUP(B5, 'Input - Vessel List'!$B$2:$M$15, 11,0) -> 11.72093 | W5: =VLOOKUP(B5, 'Input - Vessel List'!$B$2:$M$15, 12,0) -> 0.98455814 | X5: =((R5*L5*V5)+(R5*L5*W5))*-1 -> -159822.34 | Y5: =S5*O5*W5*2*-1 -> -17456.216 | Z5: =T5*O5*W5*-1 -> -581.87386 | AA5: =SUM(X5:Z5) -> -177860.43 | AB5: =2.05*F5*-1*2 -> -123000 | AD5: =VLOOKUP(B5,'Input - Vessel List'!B:C,2,0) -> 12000 | AE5: =AD5*U5*-1 -> -491500 | AF5: =AA5+AB5+AE5+AC5 -> -792360.43 | AG5: =AF5/F5*-1 -> 26.412014
A6: 5 | B6: Handysize | C6: Gresik | D6: Taiwan | E6: Taichung | F6: 30000 | G6: 4000 | H6: =200*20 -> 4000 | I6: 1 | J6: 0 | K6: VLSFO | L6: =IF(K6 ="VLSFO", $N$2,$O$2) -> 504 | M6: Singapore | N6: =VLOOKUP(M6, 'Input - Bunker'!$A$2:$C$5,2,0) -> 504 | O6: =VLOOKUP(M6, 'Input - Bunker'!$A$2:$C$5,3,0) -> 591 | P6: ='Input - OD Intl'!F10 -> 2059 | Q6: =VLOOKUP(B6, 'Input - Vessel List'!$B$2:$K$11, 7,0) -> 10 | R6: =P6*2/(Q6*24) -> 17.158333 | S6: =(F6/G6)+(F6/H6) -> 15 | T6: =I6+J6 -> 1 | U6: =SUM(R6:T6) -> 33.158333 | V6: =VLOOKUP(B6, 'Input - Vessel List'!$B$2:$M$15, 11,0) -> 11.72093 | W6: =VLOOKUP(B6, 'Input - Vessel List'!$B$2:$M$15, 12,0) -> 0.98455814 | X6: =((R6*L6*V6)+(R6*L6*W6))*-1 -> -109874.52 | Y6: =S6*O6*W6*2*-1 -> -17456.216 | Z6: =T6*O6*W6*-1 -> -581.87386 | AA6: =SUM(X6:Z6) -> -127912.61 | AB6: =2.05*F6*-1*2 -> -123000 | AD6: =VLOOKUP(B6,'Input - Vessel List'!B:C,2,0) -> 12000 | AE6: =AD6*U6*-1 -> -397900 | AF6: =AA6+AB6+AE6+AC6 -> -648812.61 | AG6: =AF6/F6*-1 -> 21.627087
A7: 6 | B7: Handysize | C7: Gresik | D7: WC-India | E7: Mundra | F7: 30000 | G7: 4000 | H7: =200*20 -> 4000 | I7: 1 | J7: 0 | K7: VLSFO | L7: =IF(K7 ="VLSFO", $N$2,$O$2) -> 504 | M7: Singapore | N7: =VLOOKUP(M7, 'Input - Bunker'!$A$2:$C$5,2,0) -> 504 | O7: =VLOOKUP(M7, 'Input - Bunker'!$A$2:$C$5,3,0) -> 591 | P7: ='Input - OD Intl'!F11 -> 3414 | Q7: =VLOOKUP(B7, 'Input - Vessel List'!$B$2:$K$11, 7,0) -> 10 | R7: =P7*2/(Q7*24) -> 28.45 | S7: =(F7/G7)+(F7/H7) -> 15 | T7: =I7+J7 -> 1 | U7: =SUM(R7:T7) -> 44.45 | V7: =VLOOKUP(B7, 'Input - Vessel List'!$B$2:$M$15, 11,0) -> 11.72093 | W7: =VLOOKUP(B7, 'Input - Vessel List'!$B$2:$M$15, 12,0) -> 0.98455814 | X7: =((R7*L7*V7)+(R7*L7*W7))*-1 -> -182181.46 | Y7: =S7*O7*W7*2*-1 -> -17456.216 | Z7: =T7*O7*W7*-1 -> -581.87386 | AA7: =SUM(X7:Z7) -> -200219.55 | AB7: =2.05*F7*-1*2 -> -123000 | AD7: =VLOOKUP(B7,'Input - Vessel List'!B:C,2,0) -> 12000 | AE7: =AD7*U7*-1 -> -533400 | AF7: =AA7+AB7+AE7+AC7 -> -856619.55 | AG7: =AF7/F7*-1 -> 28.553985
A8: 7 | B8: Handysize | C8: Gresik | D8: Australia | E8: Geelong | F8: 30000 | G8: 4000 | H8: =200*20 -> 4000 | I8: 1 | J8: 0 | K8: VLSFO | L8: =IF(K8 ="VLSFO", $N$2,$O$2) -> 504 | M8: Singapore | N8: =VLOOKUP(M8, 'Input - Bunker'!$A$2:$C$5,2,0) -> 504 | O8: =VLOOKUP(M8, 'Input - Bunker'!$A$2:$C$5,3,0) -> 591 | P8: ='Input - OD Intl'!F12 -> 3242 | Q8: =VLOOKUP(B8, 'Input - Vessel List'!$B$2:$K$11, 7,0) -> 10 | R8: =P8*2/(Q8*24) -> 27.016667 | S8: =(F8/G8)+(F8/H8) -> 15 | T8: =I8+J8 -> 1 | U8: =SUM(R8:T8) -> 43.016667 | V8: =VLOOKUP(B8, 'Input - Vessel List'!$B$2:$M$15, 11,0) -> 11.72093 | W8: =VLOOKUP(B8, 'Input - Vessel List'!$B$2:$M$15, 12,0) -> 0.98455814 | X8: =((R8*L8*V8)+(R8*L8*W8))*-1 -> -173003.01 | Y8: =S8*O8*W8*2*-1 -> -17456.216 | Z8: =T8*O8*W8*-1 -> -581.87386 | AA8: =SUM(X8:Z8) -> -191041.1 | AB8: =2.05*F8*-1*2 -> -123000 | AD8: =VLOOKUP(B8,'Input - Vessel List'!B:C,2,0) -> 12000 | AE8: =AD8*U8*-1 -> -516200 | AF8: =AA8+AB8+AE8+AC8 -> -830241.1 | AG8: =AF8/F8*-1 -> 27.674703
A9: 8 | B9: Handysize | C9: Gresik | D9: North Afrika | E9: Jorf Lasfar | F9: 30000 | G9: 4000 | H9: =200*20 -> 4000 | I9: 1 | J9: 0 | K9: VLSFO | L9: =IF(K9 ="VLSFO", $N$2,$O$2) -> 504 | M9: Singapore | N9: =VLOOKUP(M9, 'Input - Bunker'!$A$2:$C$5,2,0) -> 504 | O9: =VLOOKUP(M9, 'Input - Bunker'!$A$2:$C$5,3,0) -> 591 | P9: ='Input - OD Intl'!F13 -> 7821 | Q9: =VLOOKUP(B9, 'Input - Vessel List'!$B$2:$K$11, 7,0) -> 10 | R9: =P9*2/(Q9*24) -> 65.175 | S9: =(F9/G9)+(F9/H9) -> 15 | T9: =I9+J9 -> 1 | U9: =SUM(R9:T9) -> 81.175 | V9: =VLOOKUP(B9, 'Input - Vessel List'!$B$2:$M$15, 11,0) -> 11.72093 | W9: =VLOOKUP(B9, 'Input - Vessel List'!$B$2:$M$15, 12,0) -> 0.98455814 | X9: =((R9*L9*V9)+(R9*L9*W9))*-1 -> -417352.42 | Y9: =S9*O9*W9*2*-1 -> -17456.216 | Z9: =T9*O9*W9*-1 -> -581.87386 | AA9: =SUM(X9:Z9) -> -435390.51 | AB9: =2.05*F9*-1*2 -> -123000 | AD9: =VLOOKUP(B9,'Input - Vessel List'!B:C,2,0) -> 12000 | AE9: =AD9*U9*-1 -> -974100 | AF9: =AA9+AB9+AE9+AC9 -> -1532490.5 | AG9: =AF9/F9*-1 -> 51.083017
A10: 9 | B10: Handysize | C10: Gresik | D10: Brazil | E10: Santos | F10: 30000 | G10: 4000 | H10: =200*20 -> 4000 | I10: 1 | J10: 0 | K10: VLSFO | L10: =IF(K10 ="VLSFO", $N$2,$O$2) -> 504 | M10: Singapore | N10: =VLOOKUP(M10, 'Input - Bunker'!$A$2:$C$5,2,0) -> 504 | O10: =VLOOKUP(M10, 'Input - Bunker'!$A$2:$C$5,3,0) -> 591 | P10: ='Input - OD Intl'!F14 -> 8825 | Q10: =VLOOKUP(B10, 'Input - Vessel List'!$B$2:$K$11, 7,0) -> 10 | R10: =P10*2/(Q10*24) -> 73.541667 | S10: =(F10/G10)+(F10/H10) -> 15 | T10: =I10+J10 -> 1 | U10: =SUM(R10:T10) -> 89.541667 | V10: =VLOOKUP(B10, 'Input - Vessel List'!$B$2:$M$15, 11,0) -> 11.72093 | W10: =VLOOKUP(B10, 'Input - Vessel List'!$B$2:$M$15, 12,0) -> 0.98455814 | X10: =((R10*L10*V10)+(R10*L10*W10))*-1 -> -470928.93 | Y10: =S10*O10*W10*2*-1 -> -17456.216 | Z10: =T10*O10*W10*-1 -> -581.87386 | AA10: =SUM(X10:Z10) -> -488967.02 | AB10: =2.05*F10*-1*2 -> -123000 | AD10: =VLOOKUP(B10,'Input - Vessel List'!B:C,2,0) -> 12000 | AE10: =AD10*U10*-1 -> -1074500 | AF10: =AA10+AB10+AE10+AC10 -> -1686467 | AG10: =AF10/F10*-1 -> 56.215567
A11: 10 | B11: Handysize | C11: Gresik | D11: Philippine | E11: Davao | F11: 30000 | G11: 4000 | H11: =200*20 -> 4000 | I11: 1 | J11: 0 | K11: VLSFO | L11: =IF(K11 ="VLSFO", $N$2,$O$2) -> 504 | M11: Singapore | N11: =VLOOKUP(M11, 'Input - Bunker'!$A$2:$C$5,2,0) -> 504 | O11: =VLOOKUP(M11, 'Input - Bunker'!$A$2:$C$5,3,0) -> 591 | P11: ='Input - OD Intl'!F15 -> 1207 | Q11: =VLOOKUP(B11, 'Input - Vessel List'!$B$2:$K$11, 7,0) -> 10 | R11: =P11*2/(Q11*24) -> 10.058333 | S11: =(F11/G11)+(F11/H11) -> 15 | T11: =I11+J11 -> 1 | U11: =SUM(R11:T11) -> 26.058333 | V11: =VLOOKUP(B11, 'Input - Vessel List'!$B$2:$M$15, 11,0) -> 11.72093 | W11: =VLOOKUP(B11, 'Input - Vessel List'!$B$2:$M$15, 12,0) -> 0.98455814 | X11: =((R11*L11*V11)+(R11*L11*W11))*-1 -> -64409.203 | Y11: =S11*O11*W11*2*-1 -> -17456.216 | Z11: =T11*O11*W11*-1 -> -581.87386 | AA11: =SUM(X11:Z11) -> -82447.292 | AB11: =2.05*F11*-1*2 -> -123000 | AD11: =VLOOKUP(B11,'Input - Vessel List'!B:C,2,0) -> 12000 | AE11: =AD11*U11*-1 -> -312700 | AF11: =AA11+AB11+AE11+AC11 -> -518147.29 | AG11: =AF11/F11*-1 -> 17.271576
A12: 11 | B12: Handysize | C12: Gresik | D12: Thailand | E12: Bangkok | F12: 30000 | G12: 4000 | H12: =200*20 -> 4000 | I12: 1 | J12: 0 | K12: VLSFO | L12: =IF(K12 ="VLSFO", $N$2,$O$2) -> 504 | M12: Singapore | N12: =VLOOKUP(M12, 'Input - Bunker'!$A$2:$C$5,2,0) -> 504 | O12: =VLOOKUP(M12, 'Input - Bunker'!$A$2:$C$5,3,0) -> 591 | P12: ='Input - OD Intl'!F16 -> 1479 | Q12: =VLOOKUP(B12, 'Input - Vessel List'!$B$2:$K$11, 7,0) -> 10 | R12: =P12*2/(Q12*24) -> 12.325 | S12: =(F12/G12)+(F12/H12) -> 15 | T12: =I12+J12 -> 1 | U12: =SUM(R12:T12) -> 28.325 | V12: =VLOOKUP(B12, 'Input - Vessel List'!$B$2:$M$15, 11,0) -> 11.72093 | W12: =VLOOKUP(B12, 'Input - Vessel List'!$B$2:$M$15, 12,0) -> 0.98455814 | X12: =((R12*L12*V12)+(R12*L12*W12))*-1 -> -78923.953 | Y12: =S12*O12*W12*2*-1 -> -17456.216 | Z12: =T12*O12*W12*-1 -> -581.87386 | AA12: =SUM(X12:Z12) -> -96962.042 | AB12: =2.05*F12*-1*2 -> -123000 | AD12: =VLOOKUP(B12,'Input - Vessel List'!B:C,2,0) -> 12000 | AE12: =AD12*U12*-1 -> -339900 | AF12: =AA12+AB12+AE12+AC12 -> -559862.04 | AG12: =AF12/F12*-1 -> 18.662068
A13: 12 | B13: Handysize | C13: Gresik | D13: Vietnam | E13: Hai Phong | F13: 30000 | G13: 4000 | H13: =200*20 -> 4000 | I13: 1 | J13: 0 | K13: VLSFO | L13: =IF(K13 ="VLSFO", $N$2,$O$2) -> 504 | M13: Singapore | N13: =VLOOKUP(M13, 'Input - Bunker'!$A$2:$C$5,2,0) -> 504 | O13: =VLOOKUP(M13, 'Input - Bunker'!$A$2:$C$5,3,0) -> 591 | P13: ='Input - OD Intl'!F17 -> 1820 | Q13: =VLOOKUP(B13, 'Input - Vessel List'!$B$2:$K$11, 7,0) -> 10 | R13: =P13*2/(Q13*24) -> 15.166667 | S13: =(F13/G13)+(F13/H13) -> 15 | T13: =I13+J13 -> 1 | U13: =SUM(R13:T13) -> 31.166667 | V13: =VLOOKUP(B13, 'Input - Vessel List'!$B$2:$M$15, 11,0) -> 11.72093 | W13: =VLOOKUP(B13, 'Input - Vessel List'!$B$2:$M$15, 12,0) -> 0.98455814 | X13: =((R13*L13*V13)+(R13*L13*W13))*-1 -> -97120.753 | Y13: =S13*O13*W13*2*-1 -> -17456.216 | Z13: =T13*O13*W13*-1 -> -581.87386 | AA13: =SUM(X13:Z13) -> -115158.84 | AB13: =2.05*F13*-1*2 -> -123000 | AD13: =VLOOKUP(B13,'Input - Vessel List'!B:C,2,0) -> 12000 | AE13: =AD13*U13*-1 -> -374000 | AF13: =AA13+AB13+AE13+AC13 -> -612158.84 | AG13: =AF13/F13*-1 -> 20.405295
A14: 13 | B14: Handysize | C14: Gresik | D14: Malaysia | E14: Port Klang | F14: 30000 | G14: 4000 | H14: =200*20 -> 4000 | I14: 1 | J14: 0 | K14: VLSFO | L14: =IF(K14 ="VLSFO", $N$2,$O$2) -> 504 | M14: Singapore | N14: =VLOOKUP(M14, 'Input - Bunker'!$A$2:$C$5,2,0) -> 504 | O14: =VLOOKUP(M14, 'Input - Bunker'!$A$2:$C$5,3,0) -> 591 | P14: ='Input - OD Intl'!F18 -> 957 | Q14: =VLOOKUP(B14, 'Input - Vessel List'!$B$2:$K$11, 7,0) -> 10 | R14: =P14*2/(Q14*24) -> 7.975 | S14: =(F14/G14)+(F14/H14) -> 15 | T14: =I14+J14 -> 1 | U14: =SUM(R14:T14) -> 23.975 | V14: =VLOOKUP(B14, 'Input - Vessel List'!$B$2:$M$15, 11,0) -> 11.72093 | W14: =VLOOKUP(B14, 'Input - Vessel List'!$B$2:$M$15, 12,0) -> 0.98455814 | X14: =((R14*L14*V14)+(R14*L14*W14))*-1 -> -51068.44 | Y14: =S14*O14*W14*2*-1 -> -17456.216 | Z14: =T14*O14*W14*-1 -> -581.87386 | AA14: =SUM(X14:Z14) -> -69106.53 | AB14: =2.05*F14*-1*2 -> -123000 | AD14: =VLOOKUP(B14,'Input - Vessel List'!B:C,2,0) -> 12000 | AE14: =AD14*U14*-1 -> -287700 | AF14: =AA14+AB14+AE14+AC14 -> -479806.53 | AG14: =AF14/F14*-1 -> 15.993551
A15: 14 | B15: Handysize | C15: Gresik | D15: Laos | F15: 30000 | G15: 4000 | H15: =200*20 -> 4000 | I15: 1 | J15: 0 | K15: VLSFO | L15: =IF(K15 ="VLSFO", $N$2,$O$2) -> 504 | M15: Singapore | N15: =VLOOKUP(M15, 'Input - Bunker'!$A$2:$C$5,2,0) -> 504 | O15: =VLOOKUP(M15, 'Input - Bunker'!$A$2:$C$5,3,0) -> 591 | P15: ='Input - OD Intl'!F19 -> 0 | Q15: =VLOOKUP(B15, 'Input - Vessel List'!$B$2:$K$11, 7,0) -> 10 | R15: =P15*2/(Q15*24) -> 0 | S15: =(F15/G15)+(F15/H15) -> 15 | T15: =I15+J15 -> 1 | U15: =SUM(R15:T15) -> 16 | V15: =VLOOKUP(B15, 'Input - Vessel List'!$B$2:$M$15, 11,0) -> 11.72093 | W15: =VLOOKUP(B15, 'Input - Vessel List'!$B$2:$M$15, 12,0) -> 0.98455814 | X15: =((R15*L15*V15)+(R15*L15*W15))*-1 -> 0 | Y15: =S15*O15*W15*2*-1 -> -17456.216 | Z15: =T15*O15*W15*-1 -> -581.87386 | AA15: =SUM(X15:Z15) -> -18038.09 | AB15: =2.05*F15*-1*2 -> -123000 | AD15: =VLOOKUP(B15,'Input - Vessel List'!B:C,2,0) -> 12000 | AE15: =AD15*U15*-1 -> -192000 | AF15: =AA15+AB15+AE15+AC15 -> -333038.09 | AG15: =AF15/F15*-1 -> 11.10127
A16: 15 | B16: Handysize | C16: Gresik | D16: WC-India | E16: Mundra | F16: 30000 | G16: 4000 | H16: =200*20 -> 4000 | I16: 1 | J16: 0 | K16: VLSFO | L16: =IF(K16 ="VLSFO", $N$2,$O$2) -> 504 | M16: Singapore | N16: =VLOOKUP(M16, 'Input - Bunker'!$A$2:$C$5,2,0) -> 504 | O16: =VLOOKUP(M16, 'Input - Bunker'!$A$2:$C$5,3,0) -> 591 | P16: ='Input - OD Intl'!F20 -> 3414 | Q16: =VLOOKUP(B16, 'Input - Vessel List'!$B$2:$K$11, 7,0) -> 10 | R16: =P16*2/(Q16*24) -> 28.45 | S16: =(F16/G16)+(F16/H16) -> 15 | T16: =I16+J16 -> 1 | U16: =SUM(R16:T16) -> 44.45 | V16: =VLOOKUP(B16, 'Input - Vessel List'!$B$2:$M$15, 11,0) -> 11.72093 | W16: =VLOOKUP(B16, 'Input - Vessel List'!$B$2:$M$15, 12,0) -> 0.98455814 | X16: =((R16*L16*V16)+(R16*L16*W16))*-1 -> -182181.46 | Y16: =S16*O16*W16*2*-1 -> -17456.216 | Z16: =T16*O16*W16*-1 -> -581.87386 | AA16: =SUM(X16:Z16) -> -200219.55 | AB16: =2.05*F16*-1*2 -> -123000 | AD16: =VLOOKUP(B16,'Input - Vessel List'!B:C,2,0) -> 12000 | AE16: =AD16*U16*-1 -> -533400 | AF16: =AA16+AB16+AE16+AC16 -> -856619.55 | AG16: =AF16/F16*-1 -> 28.553985
A17: 16 | B17: Handysize | C17: Gresik | D17: Morocco | E17: Jorf Lasfar | F17: 30000 | G17: 4000 | H17: =200*20 -> 4000 | I17: 1 | J17: 0 | K17: VLSFO | L17: =IF(K17 ="VLSFO", $N$2,$O$2) -> 504 | M17: Singapore | N17: =VLOOKUP(M17, 'Input - Bunker'!$A$2:$C$5,2,0) -> 504 | O17: =VLOOKUP(M17, 'Input - Bunker'!$A$2:$C$5,3,0) -> 591 | P17: ='Input - OD Intl'!F21 -> 7821 | Q17: =VLOOKUP(B17, 'Input - Vessel List'!$B$2:$K$11, 7,0) -> 10 | R17: =P17*2/(Q17*24) -> 65.175 | S17: =(F17/G17)+(F17/H17) -> 15 | T17: =I17+J17 -> 1 | U17: =SUM(R17:T17) -> 81.175 | V17: =VLOOKUP(B17, 'Input - Vessel List'!$B$2:$M$15, 11,0) -> 11.72093 | W17: =VLOOKUP(B17, 'Input - Vessel List'!$B$2:$M$15, 12,0) -> 0.98455814 | X17: =((R17*L17*V17)+(R17*L17*W17))*-1 -> -417352.42 | Y17: =S17*O17*W17*2*-1 -> -17456.216 | Z17: =T17*O17*W17*-1 -> -581.87386 | AA17: =SUM(X17:Z17) -> -435390.51 | AB17: =2.05*F17*-1*2 -> -123000 | AC17: =(9.65*5000+7.37*5000+5.83*10000+2.13*12241)*-1 -> -169473.33 | AD17: =VLOOKUP(B17,'Input - Vessel List'!B:C,2,0) -> 12000 | AE17: =AD17*U17*-1 -> -974100 | AF17: =AA17+AB17+AE17+AC17 -> -1701963.8 | AG17: =AF17/F17*-1 -> 56.732128
A18: 17 | B18: Handysize | C18: Gresik | D18: Myanmar | E18: Yangon | F18: 30000 | G18: 4000 | H18: =200*20 -> 4000 | I18: 1 | J18: 0 | K18: VLSFO | L18: =IF(K18 ="VLSFO", $N$2,$O$2) -> 504 | M18: Singapore | N18: =VLOOKUP(M18, 'Input - Bunker'!$A$2:$C$5,2,0) -> 504 | O18: =VLOOKUP(M18, 'Input - Bunker'!$A$2:$C$5,3,0) -> 591 | P18: ='Input - OD Intl'!F22 -> 1853 | Q18: =VLOOKUP(B18, 'Input - Vessel List'!$B$2:$K$11, 7,0) -> 10 | R18: =P18*2/(Q18*24) -> 15.441667 | S18: =(F18/G18)+(F18/H18) -> 15 | T18: =I18+J18 -> 1 | U18: =SUM(R18:T18) -> 31.441667 | V18: =VLOOKUP(B18, 'Input - Vessel List'!$B$2:$M$15, 11,0) -> 11.72093 | W18: =VLOOKUP(B18, 'Input - Vessel List'!$B$2:$M$15, 12,0) -> 0.98455814 | X18: =((R18*L18*V18)+(R18*L18*W18))*-1 -> -98881.734 | Y18: =S18*O18*W18*2*-1 -> -17456.216 | Z18: =T18*O18*W18*-1 -> -581.87386 | AA18: =SUM(X18:Z18) -> -116919.82 | AB18: =2.05*F18*-1*2 -> -123000 | AD18: =VLOOKUP(B18,'Input - Vessel List'!B:C,2,0) -> 12000 | AE18: =AD18*U18*-1 -> -377300 | AF18: =AA18+AB18+AE18+AC18 -> -617219.82 | AG18: =AF18/F18*-1 -> 20.573994
A19: 18 | B19: Handysize | C19: Gresik | D19: Afsel | E19: Richard's Bay | F19: 30000 | G19: 4000 | H19: =200*20 -> 4000 | I19: 1 | J19: 0 | K19: VLSFO | L19: =IF(K19 ="VLSFO", $N$2,$O$2) -> 504 | M19: Singapore | N19: =VLOOKUP(M19, 'Input - Bunker'!$A$2:$C$5,2,0) -> 504 | O19: =VLOOKUP(M19, 'Input - Bunker'!$A$2:$C$5,3,0) -> 591 | P19: ='Input - OD Intl'!F23 -> 4815 | Q19: =VLOOKUP(B19, 'Input - Vessel List'!$B$2:$K$11, 7,0) -> 10 | R19: =P19*2/(Q19*24) -> 40.125 | S19: =(F19/G19)+(F19/H19) -> 15 | T19: =I19+J19 -> 1 | U19: =SUM(R19:T19) -> 56.125 | V19: =VLOOKUP(B19, 'Input - Vessel List'!$B$2:$M$15, 11,0) -> 11.72093 | W19: =VLOOKUP(B19, 'Input - Vessel List'!$B$2:$M$15, 12,0) -> 0.98455814 | X19: =((R19*L19*V19)+(R19*L19*W19))*-1 -> -256943.09 | Y19: =S19*O19*W19*2*-1 -> -17456.216 | Z19: =T19*O19*W19*-1 -> -581.87386 | AA19: =SUM(X19:Z19) -> -274981.18 | AB19: =2.05*F19*-1*2 -> -123000 | AD19: =VLOOKUP(B19,'Input - Vessel List'!B:C,2,0) -> 12000 | AE19: =AD19*U19*-1 -> -673500 | AF19: =AA19+AB19+AE19+AC19 -> -1071481.2 | AG19: =AF19/F19*-1 -> 35.716039
A20: 19 | B20: Handysize | C20: Gresik | D20: Mesir | E20: Port Said | F20: 30000 | G20: 4000 | H20: =200*20 -> 4000 | I20: 1 | J20: 0 | K20: VLSFO | L20: =IF(K20 ="VLSFO", $N$2,$O$2) -> 504 | M20: Singapore | N20: =VLOOKUP(M20, 'Input - Bunker'!$A$2:$C$5,2,0) -> 504 | O20: =VLOOKUP(M20, 'Input - Bunker'!$A$2:$C$5,3,0) -> 591 | P20: ='Input - OD Intl'!F24 -> 5665 | Q20: =VLOOKUP(B20, 'Input - Vessel List'!$B$2:$K$11, 7,0) -> 10 | R20: =P20*2/(Q20*24) -> 47.208333 | S20: =(F20/G20)+(F20/H20) -> 15 | T20: =I20+J20 -> 1 | U20: =SUM(R20:T20) -> 63.208333 | V20: =VLOOKUP(B20, 'Input - Vessel List'!$B$2:$M$15, 11,0) -> 11.72093 | W20: =VLOOKUP(B20, 'Input - Vessel List'!$B$2:$M$15, 12,0) -> 0.98455814 | X20: =((R20*L20*V20)+(R20*L20*W20))*-1 -> -302301.68 | Y20: =S20*O20*W20*2*-1 -> -17456.216 | Z20: =T20*O20*W20*-1 -> -581.87386 | AA20: =SUM(X20:Z20) -> -320339.77 | AB20: =2.05*F20*-1*2 -> -123000 | AC20: =(9.65*5000+7.37*5000+5.83*10000+2.13*12241)*-1 -> -169473.33 | AD20: =VLOOKUP(B20,'Input - Vessel List'!B:C,2,0) -> 12000 | AE20: =AD20*U20*-1 -> -758500 | AF20: =AA20+AB20+AE20+AC20 -> -1371313.1 | AG20: =AF20/F20*-1 -> 45.710437
A21: 20 | B21: Handysize | C21: Gresik | D21: Tanzania | E21: Dar es Salaam | F21: 30000 | G21: 4000 | H21: =200*20 -> 4000 | I21: 1 | J21: 0 | K21: VLSFO | L21: =IF(K21 ="VLSFO", $N$2,$O$2) -> 504 | M21: Singapore | N21: =VLOOKUP(M21, 'Input - Bunker'!$A$2:$C$5,2,0) -> 504 | O21: =VLOOKUP(M21, 'Input - Bunker'!$A$2:$C$5,3,0) -> 591 | P21: ='Input - OD Intl'!F25 -> 4413 | Q21: =VLOOKUP(B21, 'Input - Vessel List'!$B$2:$K$11, 7,0) -> 10 | R21: =P21*2/(Q21*24) -> 36.775 | S21: =(F21/G21)+(F21/H21) -> 15 | T21: =I21+J21 -> 1 | U21: =SUM(R21:T21) -> 52.775 | V21: =VLOOKUP(B21, 'Input - Vessel List'!$B$2:$M$15, 11,0) -> 11.72093 | W21: =VLOOKUP(B21, 'Input - Vessel List'!$B$2:$M$15, 12,0) -> 0.98455814 | X21: =((R21*L21*V21)+(R21*L21*W21))*-1 -> -235491.14 | Y21: =S21*O21*W21*2*-1 -> -17456.216 | Z21: =T21*O21*W21*-1 -> -581.87386 | AA21: =SUM(X21:Z21) -> -253529.23 | AB21: =2.05*F21*-1*2 -> -123000 | AD21: =VLOOKUP(B21,'Input - Vessel List'!B:C,2,0) -> 12000 | AE21: =AD21*U21*-1 -> -633300 | AF21: =AA21+AB21+AE21+AC21 -> -1009829.2 | AG21: =AF21/F21*-1 -> 33.660974
A22: 21 | B22: Handysize | C22: Gresik | D22: Ghana | E22: Tema | F22: 30000 | G22: 4000 | H22: =200*20 -> 4000 | I22: 1 | J22: 0 | K22: VLSFO | L22: =IF(K22 ="VLSFO", $N$2,$O$2) -> 504 | M22: Singapore | N22: =VLOOKUP(M22, 'Input - Bunker'!$A$2:$C$5,2,0) -> 504 | O22: =VLOOKUP(M22, 'Input - Bunker'!$A$2:$C$5,3,0) -> 591 | P22: ='Input - OD Intl'!F26 -> 8140 | Q22: =VLOOKUP(B22, 'Input - Vessel List'!$B$2:$K$11, 7,0) -> 10 | R22: =P22*2/(Q22*24) -> 67.833333 | S22: =(F22/G22)+(F22/H22) -> 15 | T22: =I22+J22 -> 1 | U22: =SUM(R22:T22) -> 83.833333 | V22: =VLOOKUP(B22, 'Input - Vessel List'!$B$2:$M$15, 11,0) -> 11.72093 | W22: =VLOOKUP(B22, 'Input - Vessel List'!$B$2:$M$15, 12,0) -> 0.98455814 | X22: =((R22*L22*V22)+(R22*L22*W22))*-1 -> -434375.24 | Y22: =S22*O22*W22*2*-1 -> -17456.216 | Z22: =T22*O22*W22*-1 -> -581.87386 | AA22: =SUM(X22:Z22) -> -452413.33 | AB22: =2.05*F22*-1*2 -> -123000 | AD22: =VLOOKUP(B22,'Input - Vessel List'!B:C,2,0) -> 12000 | AE22: =AD22*U22*-1 -> -1006000 | AF22: =AA22+AB22+AE22+AC22 -> -1581413.3 | AG22: =AF22/F22*-1 -> 52.713778
A23: 22 | B23: Handy SR | C23: Gresik | D23: Jepang | E23: Niihama | F23: 15000 | G23: =200*24 -> 4800 | H23: =200*24 -> 4800 | I23: 1 | J23: 0 | K23: VLSFO | L23: =IF(K23 ="VLSFO", $N$2,$O$2) -> 504 | M23: Singapore | N23: =VLOOKUP(M23, 'Input - Bunker'!$A$2:$C$5,2,0) -> 504 | O23: =VLOOKUP(M23, 'Input - Bunker'!$A$2:$C$5,3,0) -> 591 | P23: ='Input - OD Intl'!F27 -> 2918 | Q23: =VLOOKUP(B23, 'Input - Vessel List'!$B$2:$K$11, 7,0) -> 10 | R23: =P23*2/(Q23*24) -> 24.316667 | S23: =(F23/G23)+(F23/H23) -> 6.25 | T23: =I23+J23 -> 1 | U23: =SUM(R23:T23) -> 31.566667 | V23: =VLOOKUP(B23, 'Input - Vessel List'!$B$2:$M$15, 11,0) -> 11.72093 | W23: =VLOOKUP(B23, 'Input - Vessel List'!$B$2:$M$15, 12,0) -> 1.5237209 | X23: =((R23*L23*V23)+(R23*L23*W23))*-1 -> -162321.15 | Y23: =S23*O23*W23*2*-1 -> -11256.488 | Z23: =T23*O23*W23*-1 -> -900.51907 | AA23: =SUM(X23:Z23) -> -174478.15 | AB23: =2.05*F23*-1*2 -> -61500 | AD23: =VLOOKUP(B23,'Input - Vessel List'!B:C,2,0) -> 25809 | AE23: =AD23*U23*-1 -> -814704.1 | AF23: =AA23+AB23+AE23+AC23 -> -1050682.3 | AG23: =AF23/F23*-1 -> 70.045484
A24: 23 | B24: Handy SR | C24: Gresik | D24: South Korea | E24: Busan | F24: 15000 | G24: =200*24 -> 4800 | H24: =200*24 -> 4800 | I24: 1 | J24: 0 | K24: VLSFO | L24: =IF(K24 ="VLSFO", $N$2,$O$2) -> 504 | M24: Singapore | N24: =VLOOKUP(M24, 'Input - Bunker'!$A$2:$C$5,2,0) -> 504 | O24: =VLOOKUP(M24, 'Input - Bunker'!$A$2:$C$5,3,0) -> 591 | P24: ='Input - OD Intl'!F28 -> 2809 | Q24: =VLOOKUP(B24, 'Input - Vessel List'!$B$2:$K$11, 7,0) -> 10 | R24: =P24*2/(Q24*24) -> 23.408333 | S24: =(F24/G24)+(F24/H24) -> 6.25 | T24: =I24+J24 -> 1 | U24: =SUM(R24:T24) -> 30.658333 | V24: =VLOOKUP(B24, 'Input - Vessel List'!$B$2:$M$15, 11,0) -> 11.72093 | W24: =VLOOKUP(B24, 'Input - Vessel List'!$B$2:$M$15, 12,0) -> 1.5237209 | X24: =((R24*L24*V24)+(R24*L24*W24))*-1 -> -156257.75 | Y24: =S24*O24*W24*2*-1 -> -11256.488 | Z24: =T24*O24*W24*-1 -> -900.51907 | AA24: =SUM(X24:Z24) -> -168414.75 | AB24: =2.05*F24*-1*2 -> -61500 | AD24: =VLOOKUP(B24,'Input - Vessel List'!B:C,2,0) -> 25809 | AE24: =AD24*U24*-1 -> -791260.93 | AF24: =AA24+AB24+AE24+AC24 -> -1021175.7 | AG24: =AF24/F24*-1 -> 68.078379
A25: 24 | B25: Handy SR | C25: Gresik | D25: China | E25: Zhoushan | F25: 15000 | G25: =200*24 -> 4800 | H25: =200*24 -> 4800 | I25: 1 | J25: 0 | K25: VLSFO | L25: =IF(K25 ="VLSFO", $N$2,$O$2) -> 504 | M25: Singapore | N25: =VLOOKUP(M25, 'Input - Bunker'!$A$2:$C$5,2,0) -> 504 | O25: =VLOOKUP(M25, 'Input - Bunker'!$A$2:$C$5,3,0) -> 591 | P25: ='Input - OD Intl'!F29 -> 2415 | Q25: =VLOOKUP(B25, 'Input - Vessel List'!$B$2:$K$11, 7,0) -> 10 | R25: =P25*2/(Q25*24) -> 20.125 | S25: =(F25/G25)+(F25/H25) -> 6.25 | T25: =I25+J25 -> 1 | U25: =SUM(R25:T25) -> 27.375 | V25: =VLOOKUP(B25, 'Input - Vessel List'!$B$2:$M$15, 11,0) -> 11.72093 | W25: =VLOOKUP(B25, 'Input - Vessel List'!$B$2:$M$15, 12,0) -> 1.5237209 | X25: =((R25*L25*V25)+(R25*L25*W25))*-1 -> -134340.5 | Y25: =S25*O25*W25*2*-1 -> -11256.488 | Z25: =T25*O25*W25*-1 -> -900.51907 | AA25: =SUM(X25:Z25) -> -146497.5 | AB25: =2.05*F25*-1*2 -> -61500 | AD25: =VLOOKUP(B25,'Input - Vessel List'!B:C,2,0) -> 25809 | AE25: =AD25*U25*-1 -> -706521.38 | AF25: =AA25+AB25+AE25+AC25 -> -914518.88 | AG25: =AF25/F25*-1 -> 60.967925
A26: 25 | B26: Handy SR | C26: Gresik | D26: Australia | E26: Gladstone | F26: 15000 | G26: =200*24 -> 4800 | H26: =200*24 -> 4800 | I26: 1 | J26: 0 | K26: VLSFO | L26: =IF(K26 ="VLSFO", $N$2,$O$2) -> 504 | M26: Singapore | N26: =VLOOKUP(M26, 'Input - Bunker'!$A$2:$C$5,2,0) -> 504 | O26: =VLOOKUP(M26, 'Input - Bunker'!$A$2:$C$5,3,0) -> 591 | P26: ='Input - OD Intl'!F30 -> 1630 | Q26: =VLOOKUP(B26, 'Input - Vessel List'!$B$2:$K$11, 7,0) -> 10 | R26: =P26*2/(Q26*24) -> 13.583333 | S26: =(F26/G26)+(F26/H26) -> 6.25 | T26: =I26+J26 -> 1 | U26: =SUM(R26:T26) -> 20.833333 | V26: =VLOOKUP(B26, 'Input - Vessel List'!$B$2:$M$15, 11,0) -> 11.72093 | W26: =VLOOKUP(B26, 'Input - Vessel List'!$B$2:$M$15, 12,0) -> 1.5237209 | X26: =((R26*L26*V26)+(R26*L26*W26))*-1 -> -90672.882 | Y26: =S26*O26*W26*2*-1 -> -11256.488 | Z26: =T26*O26*W26*-1 -> -900.51907 | AA26: =SUM(X26:Z26) -> -102829.89 | AB26: =2.05*F26*-1*2 -> -61500 | AD26: =VLOOKUP(B26,'Input - Vessel List'!B:C,2,0) -> 25809 | AE26: =AD26*U26*-1 -> -537687.5 | AF26: =AA26+AB26+AE26+AC26 -> -702017.39 | AG26: =AF26/F26*-1 -> 46.801159
A27: 26 | B27: Handy SR | C27: Gresik | D27: WC-India | E27: Tuticorin | F27: 15000 | G27: =200*24 -> 4800 | H27: =200*24 -> 4800 | I27: 1 | J27: 0 | K27: VLSFO | L27: =IF(K27 ="VLSFO", $N$2,$O$2) -> 504 | M27: Singapore | N27: =VLOOKUP(M27, 'Input - Bunker'!$A$2:$C$5,2,0) -> 504 | O27: =VLOOKUP(M27, 'Input - Bunker'!$A$2:$C$5,3,0) -> 591 | P27: ='Input - OD Intl'!F31 -> 2363 | Q27: =VLOOKUP(B27, 'Input - Vessel List'!$B$2:$K$11, 7,0) -> 10 | R27: =P27*2/(Q27*24) -> 19.691667 | S27: =(F27/G27)+(F27/H27) -> 6.25 | T27: =I27+J27 -> 1 | U27: =SUM(R27:T27) -> 26.941667 | V27: =VLOOKUP(B27, 'Input - Vessel List'!$B$2:$M$15, 11,0) -> 11.72093 | W27: =VLOOKUP(B27, 'Input - Vessel List'!$B$2:$M$15, 12,0) -> 1.5237209 | X27: =((R27*L27*V27)+(R27*L27*W27))*-1 -> -131447.86 | Y27: =S27*O27*W27*2*-1 -> -11256.488 | Z27: =T27*O27*W27*-1 -> -900.51907 | AA27: =SUM(X27:Z27) -> -143604.87 | AB27: =2.05*F27*-1*2 -> -61500 | AD27: =VLOOKUP(B27,'Input - Vessel List'!B:C,2,0) -> 25809 | AE27: =AD27*U27*-1 -> -695337.47 | AF27: =AA27+AB27+AE27+AC27 -> -900442.35 | AG27: =AF27/F27*-1 -> 60.02949
A28: 27 | B28: Handy SR | C28: Gresik | D28: Myanmar | E28: Yangon | F28: 15000 | G28: =200*24 -> 4800 | H28: =200*24 -> 4800 | I28: 1 | J28: 0 | K28: VLSFO | L28: =IF(K28 ="VLSFO", $N$2,$O$2) -> 504 | M28: Singapore | N28: =VLOOKUP(M28, 'Input - Bunker'!$A$2:$C$5,2,0) -> 504 | O28: =VLOOKUP(M28, 'Input - Bunker'!$A$2:$C$5,3,0) -> 591 | P28: ='Input - OD Intl'!F32 -> 1853 | Q28: =VLOOKUP(B28, 'Input - Vessel List'!$B$2:$K$11, 7,0) -> 10 | R28: =P28*2/(Q28*24) -> 15.441667 | S28: =(F28/G28)+(F28/H28) -> 6.25 | T28: =I28+J28 -> 1 | U28: =SUM(R28:T28) -> 22.691667 | V28: =VLOOKUP(B28, 'Input - Vessel List'!$B$2:$M$15, 11,0) -> 11.72093 | W28: =VLOOKUP(B28, 'Input - Vessel List'!$B$2:$M$15, 12,0) -> 1.5237209 | X28: =((R28*L28*V28)+(R28*L28*W28))*-1 -> -103077.82 | Y28: =S28*O28*W28*2*-1 -> -11256.488 | Z28: =T28*O28*W28*-1 -> -900.51907 | AA28: =SUM(X28:Z28) -> -115234.83 | AB28: =2.05*F28*-1*2 -> -61500 | AD28: =VLOOKUP(B28,'Input - Vessel List'!B:C,2,0) -> 25809 | AE28: =AD28*U28*-1 -> -585649.22 | AF28: =AA28+AB28+AE28+AC28 -> -762384.05 | AG28: =AF28/F28*-1 -> 50.825604
A29: 28 | B29: Handy SR | C29: Gresik | D29: Thailand | E29: Bangkok | F29: 15000 | G29: =200*24 -> 4800 | H29: =200*24 -> 4800 | I29: 1 | J29: 0 | K29: VLSFO | L29: =IF(K29 ="VLSFO", $N$2,$O$2) -> 504 | M29: Singapore | N29: =VLOOKUP(M29, 'Input - Bunker'!$A$2:$C$5,2,0) -> 504 | O29: =VLOOKUP(M29, 'Input - Bunker'!$A$2:$C$5,3,0) -> 591 | P29: ='Input - OD Intl'!F33 -> 1479 | Q29: =VLOOKUP(B29, 'Input - Vessel List'!$B$2:$K$11, 7,0) -> 10 | R29: =P29*2/(Q29*24) -> 12.325 | S29: =(F29/G29)+(F29/H29) -> 6.25 | T29: =I29+J29 -> 1 | U29: =SUM(R29:T29) -> 19.575 | V29: =VLOOKUP(B29, 'Input - Vessel List'!$B$2:$M$15, 11,0) -> 11.72093 | W29: =VLOOKUP(B29, 'Input - Vessel List'!$B$2:$M$15, 12,0) -> 1.5237209 | X29: =((R29*L29*V29)+(R29*L29*W29))*-1 -> -82273.124 | Y29: =S29*O29*W29*2*-1 -> -11256.488 | Z29: =T29*O29*W29*-1 -> -900.51907 | AA29: =SUM(X29:Z29) -> -94430.132 | AB29: =2.05*F29*-1*2 -> -61500 | AD29: =VLOOKUP(B29,'Input - Vessel List'!B:C,2,0) -> 25809 | AE29: =AD29*U29*-1 -> -505211.17 | AF29: =AA29+AB29+AE29+AC29 -> -661141.31 | AG29: =AF29/F29*-1 -> 44.076087
A30: 29 | B30: Handy SR | C30: Gresik | D30: Taiwan | E30: Taichung | F30: 15000 | G30: =200*24 -> 4800 | H30: =200*24 -> 4800 | I30: 1 | J30: 0 | K30: VLSFO | L30: =IF(K30 ="VLSFO", $N$2,$O$2) -> 504 | M30: Singapore | N30: =VLOOKUP(M30, 'Input - Bunker'!$A$2:$C$5,2,0) -> 504 | O30: =VLOOKUP(M30, 'Input - Bunker'!$A$2:$C$5,3,0) -> 591 | P30: ='Input - OD Intl'!F34 -> 2059 | Q30: =VLOOKUP(B30, 'Input - Vessel List'!$B$2:$K$11, 7,0) -> 10 | R30: =P30*2/(Q30*24) -> 17.158333 | S30: =(F30/G30)+(F30/H30) -> 6.25 | T30: =I30+J30 -> 1 | U30: =SUM(R30:T30) -> 24.408333 | V30: =VLOOKUP(B30, 'Input - Vessel List'!$B$2:$M$15, 11,0) -> 11.72093 | W30: =VLOOKUP(B30, 'Input - Vessel List'!$B$2:$M$15, 12,0) -> 1.5237209 | X30: =((R30*L30*V30)+(R30*L30*W30))*-1 -> -114537.09 | Y30: =S30*O30*W30*2*-1 -> -11256.488 | Z30: =T30*O30*W30*-1 -> -900.51907 | AA30: =SUM(X30:Z30) -> -126694.1 | AB30: =2.05*F30*-1*2 -> -61500 | AD30: =VLOOKUP(B30,'Input - Vessel List'!B:C,2,0) -> 25809 | AE30: =AD30*U30*-1 -> -629954.68 | AF30: =AA30+AB30+AE30+AC30 -> -818148.78 | AG30: =AF30/F30*-1 -> 54.543252
A31: 30 | B31: Handysize | C31: Cigading | D31: Philippines | E31: Davao | F31: 30000 | G31: 4000 | H31: =200*20 -> 4000 | I31: 1 | J31: 0 | K31: VLSFO | L31: =IF(K31 ="VLSFO", $N$2,$O$2) -> 504 | M31: Singapore | N31: =VLOOKUP(M31, 'Input - Bunker'!$A$2:$C$5,2,0) -> 504 | O31: =VLOOKUP(M31, 'Input - Bunker'!$A$2:$C$5,3,0) -> 591 | P31: ='Input - OD Intl'!G6 -> 1561 | Q31: =VLOOKUP(B31, 'Input - Vessel List'!$B$2:$K$11, 7,0) -> 10 | R31: =P31*2/(Q31*24) -> 13.008333 | S31: =(F31/G31)+(F31/H31) -> 15 | T31: =I31+J31 -> 1 | U31: =SUM(R31:T31) -> 29.008333 | V31: =VLOOKUP(B31, 'Input - Vessel List'!$B$2:$M$15, 11,0) -> 11.72093 | W31: =VLOOKUP(B31, 'Input - Vessel List'!$B$2:$M$15, 12,0) -> 0.98455814 | X31: =((R31*L31*V31)+(R31*L31*W31))*-1 -> -83299.723 | Y31: =S31*O31*W31*2*-1 -> -17456.216 | Z31: =T31*O31*W31*-1 -> -581.87386 | AA31: =SUM(X31:Z31) -> -101337.81 | AB31: =2.05*F31*-1*2 -> -123000 | AD31: =VLOOKUP(B31,'Input - Vessel List'!B:C,2,0) -> 12000 | AE31: =AD31*U31*-1 -> -348100 | AF31: =AA31+AB31+AE31+AC31 -> -572437.81 | AG31: =AF31/F31*-1 -> 19.08126
A32: 31 | B32: Handysize | C32: Cigading | D32: Thailand | E32: Bangkok | F32: 30000 | G32: 4000 | H32: =200*20 -> 4000 | I32: 1 | J32: 0 | K32: VLSFO | L32: =IF(K32 ="VLSFO", $N$2,$O$2) -> 504 | M32: Singapore | N32: =VLOOKUP(M32, 'Input - Bunker'!$A$2:$C$5,2,0) -> 504 | O32: =VLOOKUP(M32, 'Input - Bunker'!$A$2:$C$5,3,0) -> 591 | P32: ='Input - OD Intl'!G7 -> 1303 | Q32: =VLOOKUP(B32, 'Input - Vessel List'!$B$2:$K$11, 7,0) -> 10 | R32: =P32*2/(Q32*24) -> 10.858333 | S32: =(F32/G32)+(F32/H32) -> 15 | T32: =I32+J32 -> 1 | U32: =SUM(R32:T32) -> 26.858333 | V32: =VLOOKUP(B32, 'Input - Vessel List'!$B$2:$M$15, 11,0) -> 11.72093 | W32: =VLOOKUP(B32, 'Input - Vessel List'!$B$2:$M$15, 12,0) -> 0.98455814 | X32: =((R32*L32*V32)+(R32*L32*W32))*-1 -> -69532.056 | Y32: =S32*O32*W32*2*-1 -> -17456.216 | Z32: =T32*O32*W32*-1 -> -581.87386 | AA32: =SUM(X32:Z32) -> -87570.145 | AB32: =2.05*F32*-1*2 -> -123000 | AD32: =VLOOKUP(B32,'Input - Vessel List'!B:C,2,0) -> 12000 | AE32: =AD32*U32*-1 -> -322300 | AF32: =AA32+AB32+AE32+AC32 -> -532870.15 | AG32: =AF32/F32*-1 -> 17.762338
A33: 32 | B33: Handysize | C33: Cigading | D33: Vietnam | E33: Hai Phong | F33: 30000 | G33: 4000 | H33: =200*20 -> 4000 | I33: 1 | J33: 0 | K33: VLSFO | L33: =IF(K33 ="VLSFO", $N$2,$O$2) -> 504 | M33: Singapore | N33: =VLOOKUP(M33, 'Input - Bunker'!$A$2:$C$5,2,0) -> 504 | O33: =VLOOKUP(M33, 'Input - Bunker'!$A$2:$C$5,3,0) -> 591 | P33: ='Input - OD Intl'!G8 -> 1684 | Q33: =VLOOKUP(B33, 'Input - Vessel List'!$B$2:$K$11, 7,0) -> 10 | R33: =P33*2/(Q33*24) -> 14.033333 | S33: =(F33/G33)+(F33/H33) -> 15 | T33: =I33+J33 -> 1 | U33: =SUM(R33:T33) -> 30.033333 | V33: =VLOOKUP(B33, 'Input - Vessel List'!$B$2:$M$15, 11,0) -> 11.72093 | W33: =VLOOKUP(B33, 'Input - Vessel List'!$B$2:$M$15, 12,0) -> 0.98455814 | X33: =((R33*L33*V33)+(R33*L33*W33))*-1 -> -89863.378 | Y33: =S33*O33*W33*2*-1 -> -17456.216 | Z33: =T33*O33*W33*-1 -> -581.87386 | AA33: =SUM(X33:Z33) -> -107901.47 | AB33: =2.05*F33*-1*2 -> -123000 | AD33: =VLOOKUP(B33,'Input - Vessel List'!B:C,2,0) -> 12000 | AE33: =AD33*U33*-1 -> -360400 | AF33: =AA33+AB33+AE33+AC33 -> -591301.47 | AG33: =AF33/F33*-1 -> 19.710049
A34: 33 | B34: Handysize | C34: Cigading | D34: Jepang | E34: Nagoya | F34: 30000 | G34: 4000 | H34: =200*20 -> 4000 | I34: 1 | J34: 0 | K34: VLSFO | L34: =IF(K34 ="VLSFO", $N$2,$O$2) -> 504 | M34: Singapore | N34: =VLOOKUP(M34, 'Input - Bunker'!$A$2:$C$5,2,0) -> 504 | O34: =VLOOKUP(M34, 'Input - Bunker'!$A$2:$C$5,3,0) -> 591 | P34: ='Input - OD Intl'!G9 -> 3084 | Q34: =VLOOKUP(B34, 'Input - Vessel List'!$B$2:$K$11, 7,0) -> 10 | R34: =P34*2/(Q34*24) -> 25.7 | S34: =(F34/G34)+(F34/H34) -> 15 | T34: =I34+J34 -> 1 | U34: =SUM(R34:T34) -> 41.7 | V34: =VLOOKUP(B34, 'Input - Vessel List'!$B$2:$M$15, 11,0) -> 11.72093 | W34: =VLOOKUP(B34, 'Input - Vessel List'!$B$2:$M$15, 12,0) -> 0.98455814 | X34: =((R34*L34*V34)+(R34*L34*W34))*-1 -> -164571.65 | Y34: =S34*O34*W34*2*-1 -> -17456.216 | Z34: =T34*O34*W34*-1 -> -581.87386 | AA34: =SUM(X34:Z34) -> -182609.74 | AB34: =2.05*F34*-1*2 -> -123000 | AD34: =VLOOKUP(B34,'Input - Vessel List'!B:C,2,0) -> 12000 | AE34: =AD34*U34*-1 -> -500400 | AF34: =AA34+AB34+AE34+AC34 -> -806009.74 | AG34: =AF34/F34*-1 -> 26.866991
A35: 34 | B35: Handysize | C35: Cigading | D35: Taiwan | E35: Taichung | F35: 30000 | G35: 4000 | H35: =200*20 -> 4000 | I35: 1 | J35: 0 | K35: VLSFO | L35: =IF(K35 ="VLSFO", $N$2,$O$2) -> 504 | M35: Singapore | N35: =VLOOKUP(M35, 'Input - Bunker'!$A$2:$C$5,2,0) -> 504 | O35: =VLOOKUP(M35, 'Input - Bunker'!$A$2:$C$5,3,0) -> 591 | P35: ='Input - OD Intl'!G10 -> 2061 | Q35: =VLOOKUP(B35, 'Input - Vessel List'!$B$2:$K$11, 7,0) -> 10 | R35: =P35*2/(Q35*24) -> 17.175 | S35: =(F35/G35)+(F35/H35) -> 15 | T35: =I35+J35 -> 1 | U35: =SUM(R35:T35) -> 33.175 | V35: =VLOOKUP(B35, 'Input - Vessel List'!$B$2:$M$15, 11,0) -> 11.72093 | W35: =VLOOKUP(B35, 'Input - Vessel List'!$B$2:$M$15, 12,0) -> 0.98455814 | X35: =((R35*L35*V35)+(R35*L35*W35))*-1 -> -109981.25 | Y35: =S35*O35*W35*2*-1 -> -17456.216 | Z35: =T35*O35*W35*-1 -> -581.87386 | AA35: =SUM(X35:Z35) -> -128019.34 | AB35: =2.05*F35*-1*2 -> -123000 | AD35: =VLOOKUP(B35,'Input - Vessel List'!B:C,2,0) -> 12000 | AE35: =AD35*U35*-1 -> -398100 | AF35: =AA35+AB35+AE35+AC35 -> -649119.34 | AG35: =AF35/F35*-1 -> 21.637311
A36: 35 | B36: Handysize | C36: Cigading | D36: WC-India | E36: Mundra | F36: 30000 | G36: 4000 | H36: =200*20 -> 4000 | I36: 1 | J36: 0 | K36: VLSFO | L36: =IF(K36 ="VLSFO", $N$2,$O$2) -> 504 | M36: Singapore | N36: =VLOOKUP(M36, 'Input - Bunker'!$A$2:$C$5,2,0) -> 504 | O36: =VLOOKUP(M36, 'Input - Bunker'!$A$2:$C$5,3,0) -> 591 | P36: ='Input - OD Intl'!G11 -> 2983 | Q36: =VLOOKUP(B36, 'Input - Vessel List'!$B$2:$K$11, 7,0) -> 10 | R36: =P36*2/(Q36*24) -> 24.858333 | S36: =(F36/G36)+(F36/H36) -> 15 | T36: =I36+J36 -> 1 | U36: =SUM(R36:T36) -> 40.858333 | V36: =VLOOKUP(B36, 'Input - Vessel List'!$B$2:$M$15, 11,0) -> 11.72093 | W36: =VLOOKUP(B36, 'Input - Vessel List'!$B$2:$M$15, 12,0) -> 0.98455814 | X36: =((R36*L36*V36)+(R36*L36*W36))*-1 -> -159181.98 | Y36: =S36*O36*W36*2*-1 -> -17456.216 | Z36: =T36*O36*W36*-1 -> -581.87386 | AA36: =SUM(X36:Z36) -> -177220.07 | AB36: =2.05*F36*-1*2 -> -123000 | AD36: =VLOOKUP(B36,'Input - Vessel List'!B:C,2,0) -> 12000 | AE36: =AD36*U36*-1 -> -490300 | AF36: =AA36+AB36+AE36+AC36 -> -790520.07 | AG36: =AF36/F36*-1 -> 26.350669
A37: 36 | B37: Handysize | C37: Cigading | D37: Australia | E37: Geelong | F37: 30000 | G37: 4000 | H37: =200*20 -> 4000 | I37: 1 | J37: 0 | K37: VLSFO | L37: =IF(K37 ="VLSFO", $N$2,$O$2) -> 504 | M37: Singapore | N37: =VLOOKUP(M37, 'Input - Bunker'!$A$2:$C$5,2,0) -> 504 | O37: =VLOOKUP(M37, 'Input - Bunker'!$A$2:$C$5,3,0) -> 591 | P37: ='Input - OD Intl'!G12 -> 3329 | Q37: =VLOOKUP(B37, 'Input - Vessel List'!$B$2:$K$11, 7,0) -> 10 | R37: =P37*2/(Q37*24) -> 27.741667 | S37: =(F37/G37)+(F37/H37) -> 15 | T37: =I37+J37 -> 1 | U37: =SUM(R37:T37) -> 43.741667 | V37: =VLOOKUP(B37, 'Input - Vessel List'!$B$2:$M$15, 11,0) -> 11.72093 | W37: =VLOOKUP(B37, 'Input - Vessel List'!$B$2:$M$15, 12,0) -> 0.98455814 | X37: =((R37*L37*V37)+(R37*L37*W37))*-1 -> -177645.6 | Y37: =S37*O37*W37*2*-1 -> -17456.216 | Z37: =T37*O37*W37*-1 -> -581.87386 | AA37: =SUM(X37:Z37) -> -195683.69 | AB37: =2.05*F37*-1*2 -> -123000 | AD37: =VLOOKUP(B37,'Input - Vessel List'!B:C,2,0) -> 12000 | AE37: =AD37*U37*-1 -> -524900 | AF37: =AA37+AB37+AE37+AC37 -> -843583.69 | AG37: =AF37/F37*-1 -> 28.119456
A38: 37 | B38: Handysize | C38: Cigading | D38: North Afrika | E38: Jorf Lasfar | F38: 30000 | G38: 4000 | H38: =200*20 -> 4000 | I38: 1 | J38: 0 | K38: VLSFO | L38: =IF(K38 ="VLSFO", $N$2,$O$2) -> 504 | M38: Singapore | N38: =VLOOKUP(M38, 'Input - Bunker'!$A$2:$C$5,2,0) -> 504 | O38: =VLOOKUP(M38, 'Input - Bunker'!$A$2:$C$5,3,0) -> 591 | P38: ='Input - OD Intl'!G13 -> 7390 | Q38: =VLOOKUP(B38, 'Input - Vessel List'!$B$2:$K$11, 7,0) -> 10 | R38: =P38*2/(Q38*24) -> 61.583333 | S38: =(F38/G38)+(F38/H38) -> 15 | T38: =I38+J38 -> 1 | U38: =SUM(R38:T38) -> 77.583333 | V38: =VLOOKUP(B38, 'Input - Vessel List'!$B$2:$M$15, 11,0) -> 11.72093 | W38: =VLOOKUP(B38, 'Input - Vessel List'!$B$2:$M$15, 12,0) -> 0.98455814 | X38: =((R38*L38*V38)+(R38*L38*W38))*-1 -> -394352.95 | Y38: =S38*O38*W38*2*-1 -> -17456.216 | Z38: =T38*O38*W38*-1 -> -581.87386 | AA38: =SUM(X38:Z38) -> -412391.04 | AB38: =2.05*F38*-1*2 -> -123000 | AD38: =VLOOKUP(B38,'Input - Vessel List'!B:C,2,0) -> 12000 | AE38: =AD38*U38*-1 -> -931000 | AF38: =AA38+AB38+AE38+AC38 -> -1466391 | AG38: =AF38/F38*-1 -> 48.879701
A39: 38 | B39: Handysize | C39: Cigading | D39: Brazil | E39: Santos | F39: 30000 | G39: 4000 | H39: =200*20 -> 4000 | I39: 1 | J39: 0 | K39: VLSFO | L39: =IF(K39 ="VLSFO", $N$2,$O$2) -> 504 | M39: Singapore | N39: =VLOOKUP(M39, 'Input - Bunker'!$A$2:$C$5,2,0) -> 504 | O39: =VLOOKUP(M39, 'Input - Bunker'!$A$2:$C$5,3,0) -> 591 | P39: ='Input - OD Intl'!G14 -> 8394 | Q39: =VLOOKUP(B39, 'Input - Vessel List'!$B$2:$K$11, 7,0) -> 10 | R39: =P39*2/(Q39*24) -> 69.95 | S39: =(F39/G39)+(F39/H39) -> 15 | T39: =I39+J39 -> 1 | U39: =SUM(R39:T39) -> 85.95 | V39: =VLOOKUP(B39, 'Input - Vessel List'!$B$2:$M$15, 11,0) -> 11.72093 | W39: =VLOOKUP(B39, 'Input - Vessel List'!$B$2:$M$15, 12,0) -> 0.98455814 | X39: =((R39*L39*V39)+(R39*L39*W39))*-1 -> -447929.45 | Y39: =S39*O39*W39*2*-1 -> -17456.216 | Z39: =T39*O39*W39*-1 -> -581.87386 | AA39: =SUM(X39:Z39) -> -465967.54 | AB39: =2.05*F39*-1*2 -> -123000 | AD39: =VLOOKUP(B39,'Input - Vessel List'!B:C,2,0) -> 12000 | AE39: =AD39*U39*-1 -> -1031400 | AF39: =AA39+AB39+AE39+AC39 -> -1620367.5 | AG39: =AF39/F39*-1 -> 54.012251
A40: 39 | B40: Handysize | C40: Cigading | D40: Philippine | E40: Davao | F40: 30000 | G40: 4000 | H40: =200*20 -> 4000 | I40: 1 | J40: 0 | K40: VLSFO | L40: =IF(K40 ="VLSFO", $N$2,$O$2) -> 504 | M40: Singapore | N40: =VLOOKUP(M40, 'Input - Bunker'!$A$2:$C$5,2,0) -> 504 | O40: =VLOOKUP(M40, 'Input - Bunker'!$A$2:$C$5,3,0) -> 591 | P40: ='Input - OD Intl'!G15 -> 1561 | Q40: =VLOOKUP(B40, 'Input - Vessel List'!$B$2:$K$11, 7,0) -> 10 | R40: =P40*2/(Q40*24) -> 13.008333 | S40: =(F40/G40)+(F40/H40) -> 15 | T40: =I40+J40 -> 1 | U40: =SUM(R40:T40) -> 29.008333 | V40: =VLOOKUP(B40, 'Input - Vessel List'!$B$2:$M$15, 11,0) -> 11.72093 | W40: =VLOOKUP(B40, 'Input - Vessel List'!$B$2:$M$15, 12,0) -> 0.98455814 | X40: =((R40*L40*V40)+(R40*L40*W40))*-1 -> -83299.723 | Y40: =S40*O40*W40*2*-1 -> -17456.216 | Z40: =T40*O40*W40*-1 -> -581.87386 | AA40: =SUM(X40:Z40) -> -101337.81 | AB40: =2.05*F40*-1*2 -> -123000 | AD40: =VLOOKUP(B40,'Input - Vessel List'!B:C,2,0) -> 12000 | AE40: =AD40*U40*-1 -> -348100 | AF40: =AA40+AB40+AE40+AC40 -> -572437.81 | AG40: =AF40/F40*-1 -> 19.08126
...

Sheet Output - Freight
A1: INDIKASI TARIF ANGKUTAN LAUT TUJUAN EKSPOR PI GRUP
I2: Update per tanggal 09/05/2025
A3: Jenis Produk (In Bulk / In Bag) | B3: Info Tarif Angkutan Bulan November 2024
B4: Tujuan | D4: Asal Pelabuhan | I4: Term and Condition
D5: PKG | E5: PKC | F5: PKT | G5: PIM | H5: PSP
B6: Negara | C6: Pelabuhan | D6: Gresik | E6: Cigading | F6: Bontang | G6: Lhoksumawe | H6: Palembang
A7: Urea | B7: Philippines | C7: Davao | D7: ='Process - Intl'!AG2 -> 17.271576 | E7: ='Process - Intl'!AG31 -> 19.08126 | F7: ='Process - Intl'!AG60 -> 14.006217 | G7: ='Process - Intl'!AG89 -> 18.968794 | H7: ='Process - Intl'!AG118 -> 19.648704 | I7: Handysize 30.000 ton
B8: Thailand | C8: Bangkok | D8: ='Process - Intl'!AG3 -> 18.662068 | E8: ='Process - Intl'!AG32 -> 17.762338 | F8: ='Process - Intl'!AG61 -> 19.394372 | G8: ='Process - Intl'!AG90 -> 17.854356 | H8: ='Process - Intl'!AG119 -> 16.591667 | I8: Handysize 30.000 ton
B9: Vietnam | C9: Hai Phong | D9: ='Process - Intl'!AG4 -> 20.405295 | E9: ='Process - Intl'!AG33 -> 19.710049 | F9: ='Process - Intl'!AG62 -> 18.504867 | G9: ='Process - Intl'!AG91 -> 20.251932 | H9: ='Process - Intl'!AG120 -> 18.820543 | I9: Handysize 30.000 ton
B10: Jepang | C10: Nagoya | D10: ='Process - Intl'!AG5 -> 26.412014 | E10: ='Process - Intl'!AG34 -> 26.866991 | F10: ='Process - Intl'!AG63 -> 23.146655 | G10: ='Process - Intl'!AG92 -> 27.792282 | H10: ='Process - Intl'!AG121 -> 26.238203 | I10: Handysize 30.000 ton
B11: Taiwan | C11: Taichung | D11: ='Process - Intl'!AG6 -> 21.627087 | E11: ='Process - Intl'!AG35 -> 21.637311 | F11: ='Process - Intl'!AG64 -> 18.310607 | G11: ='Process - Intl'!AG93 -> 22.286548 | H11: ='Process - Intl'!AG122 -> 20.768254 | I11: Handysize 30.000 ton
B12: WC-India | C12: Mundra | D12: ='Process - Intl'!AG7 -> 28.553985 | E12: ='Process - Intl'!AG36 -> 26.350669 | F12: ='Process - Intl'!AG65 -> 29.184093 | G12: ='Process - Intl'!AG94 -> 22.741525 | H12: ='Process - Intl'!AG123 -> 26.560265 | I12: Handysize 30.000 ton
B13: Australia | C13: Geelong | D13: ='Process - Intl'!AG8 -> 27.674703 | E13: ='Process - Intl'!AG37 -> 28.119456 | F13: ='Process - Intl'!AG66 -> 29.308575 | G13: ='Process - Intl'!AG95 -> 33.226446 | H13: ='Process - Intl'!AG124 -> 29.70932 | I13: Handysize 30.000 ton
B14: North Afrika | C14: Jorf Lasfar | D14: ='Process - Intl'!AG9 -> 51.083017 | E14: ='Process - Intl'!AG38 -> 48.879701 | F14: ='Process - Intl'!AG67 -> 52.945096 | G14: ='Process - Intl'!AG96 -> 45.337015 | H14: ='Process - Intl'!AG125 -> 49.150643 | I14: Handysize 30.000 ton
B15: Brazil | C15: Santos | D15: ='Process - Intl'!AG10 -> 56.215567 | E15: ='Process - Intl'!AG39 -> 54.012251 | F15: ='Process - Intl'!AG68 -> 57.239261 | G15: ='Process - Intl'!AG97 -> 54.523462 | H15: ='Process - Intl'!AG126 -> 55.602115 | I15: Handysize 30.000 ton
A16: NPK | B16: Philippines | C16: Davao | D16: ='Process - Intl'!AG11 -> 17.271576 | E16: ='Process - Intl'!AG40 -> 19.08126 | F16: ='Process - Intl'!AG69 -> 14.006217 | G16: ='Process - Intl'!AG98 -> 18.968794 | H16: ='Process - Intl'!AG127 -> 19.648704 | I16: Handysize 30.000 ton
B17: Thailand | C17: Bangkok | D17: ='Process - Intl'!AG12 -> 18.662068 | E17: ='Process - Intl'!AG41 -> 17.762338 | F17: ='Process - Intl'!AG70 -> 19.394372 | G17: ='Process - Intl'!AG99 -> 17.854356 | H17: ='Process - Intl'!AG128 -> 16.591667 | I17: Handysize 30.000 ton
B18: Vietnam | C18: Hai Phong | D18: ='Process - Intl'!AG13 -> 20.405295 | E18: ='Process - Intl'!AG42 -> 19.710049 | F18: ='Process - Intl'!AG71 -> 18.504867 | G18: ='Process - Intl'!AG100 -> 20.251932 | H18: ='Process - Intl'!AG129 -> 18.820543 | I18: Handysize 30.000 ton
B19: Malaysia | C19: Port Klang | D19: ='Process - Intl'!AG14 -> 15.993551 | E19: ='Process - Intl'!AG43 -> 14.914898 | F19: ='Process - Intl'!AG72 -> 17.288186 | G19: ='Process - Intl'!AG101 -> 12.650236 | H19: ='Process - Intl'!AG130 -> 13.483509 | I19: Handysize 30.000 ton
B20: Laos | D20: 0 | E20: 0 | F20: 0 | G20: 0 | H20: 0 | I20: via Thailand/Vietnam
B21: WC-India | C21: Mundra | D21: ='Process - Intl'!AG16 -> 28.553985 | E21: ='Process - Intl'!AG45 -> 26.350669 | F21: ='Process - Intl'!AG74 -> 30.410952 | G21: ='Process - Intl'!AG103 -> 22.741525 | H21: ='Process - Intl'!AG132 -> 26.560265 | I21: Handysize 30.000 ton
B22: Morocco | C22: Jorf Lasfar | D22: ='Process - Intl'!AG17 -> 56.732128 | E22: ='Process - Intl'!AG46 -> 54.528812 | F22: ='Process - Intl'!AG75 -> 58.594207 | G22: ='Process - Intl'!AG104 -> 50.986126 | H22: ='Process - Intl'!AG133 -> 54.799754 | I22: Handysize 30.000 ton
B23: Myanmar | C23: Yangon | D23: ='Process - Intl'!AG18 -> 20.573994 | E23: ='Process - Intl'!AG47 -> 19.490229 | F23: ='Process - Intl'!AG76 -> 21.863517 | G23: ='Process - Intl'!AG105 -> 14.669517 | H23: ='Process - Intl'!AG134 -> 18.05884 | I23: Handysize 30.000 ton
B24: Afrika Selatan | C24: Richard's Bay | D24: ='Process - Intl'!AG19 -> 35.716039 | E24: ='Process - Intl'!AG48 -> 33.512724 | F24: ='Process - Intl'!AG77 -> 37.578118 | G24: ='Process - Intl'!AG106 -> 33.246894 | H24: ='Process - Intl'!AG135 -> 35.102587 | I24: Handysize 30.000 ton
B25: Mesir | C25: Port Said | D25: ='Process - Intl'!AG20 -> 45.710437 | E25: ='Process - Intl'!AG49 -> 43.507121 | F25: ='Process - Intl'!AG78 -> 47.572516 | G25: ='Process - Intl'!AG107 -> 39.964435 | H25: ='Process - Intl'!AG136 -> 43.778062 | I25: Handysize 30.000 ton
B26: Tanzania | C26: Dar es Salaam | D26: ='Process - Intl'!AG21 -> 33.660974 | E26: ='Process - Intl'!AG50 -> 31.457659 | F26: ='Process - Intl'!AG79 -> 35.517941 | G26: ='Process - Intl'!AG108 -> 29.310576 | H26: ='Process - Intl'!AG137 -> 33.04241 | I26: Handysize 30.000 ton
B27: Ghana | C27: Tema | D27: ='Process - Intl'!AG22 -> 52.713778 | E27: ='Process - Intl'!AG51 -> 50.510462 | F27: ='Process - Intl'!AG80 -> 54.570744 | G27: ='Process - Intl'!AG109 -> 50.607592 | H27: ='Process - Intl'!AG138 -> 52.095213 | I27: Handysize 30.000 ton
A28: Amoniak | B28: Jepang | C28: Niihama | D28: ='Process - Intl'!AG23 -> 70.045484 | E28: ='Process - Intl'!AG52 -> 70.514701 | F28: ='Process - Intl'!AG81 -> 60.841597 | G28: ='Process - Intl'!AG110 -> 73.88946 | H28: ='Process - Intl'!AG139 -> 68.2408 | I28: Handy SR 15.000 ton
B29: South Korea | C29: Busan | D29: ='Process - Intl'!AG24 -> 68.078379 | E29: ='Process - Intl'!AG53 -> 68.800252 | F29: ='Process - Intl'!AG82 -> 58.694024 | G29: ='Process - Intl'!AG111 -> 71.074153 | H29: ='Process - Intl'!AG140 -> 65.73229 | I29: Handy SR 15.000 ton
B30: China | C30: Zhoushan | D30: ='Process - Intl'!AG25 -> 60.967925 | E30: ='Process - Intl'!AG54 -> 60.877691 | F30: ='Process - Intl'!AG83 -> 51.583571 | G30: ='Process - Intl'!AG112 -> 63.133546 | H30: ='Process - Intl'!AG141 -> 57.827776 | I30: Handy SR 15.000 ton
B31: Australia | C31: Kwinana | D31: ='Process - Intl'!AG26 -> 46.801159 | E31: ='Process - Intl'!AG55 -> 48.461468 | F31: ='Process - Intl'!AG84 -> 53.749191 | G31: ='Process - Intl'!AG113 -> 66.959475 | H31: ='Process - Intl'!AG142 -> 54.074034 | I31: Handy SR 15.000 ton
B32: WC-India | C32: Tuticorin | D32: ='Process - Intl'!AG27 -> 60.02949 | E32: ='Process - Intl'!AG56 -> 52.251304 | F32: ='Process - Intl'!AG85 -> 68.908533 | G32: ='Process - Intl'!AG114 -> 39.510238 | H32: ='Process - Intl'!AG143 -> 52.991224 | I32: Handy SR 15.000 ton
B33: Myanmar | C33: Yangon | D33: ='Process - Intl'!AG28 -> 50.825604 | E33: ='Process - Intl'!AG57 -> 46.999674 | F33: ='Process - Intl'!AG86 -> 57.701448 | G33: ='Process - Intl'!AG115 -> 29.981508 | H33: ='Process - Intl'!AG144 -> 41.94656 | I33: Handy SR 15.000 ton
B34: Thailand | C34: Bangkok | D34: ='Process - Intl'!AG29 -> 44.076087 | E34: ='Process - Intl'!AG58 -> 40.899844 | F34: ='Process - Intl'!AG87 -> 48.984826 | G34: ='Process - Intl'!AG116 -> 41.224687 | H34: ='Process - Intl'!AG145 -> 36.767119 | I34: Handy SR 15.000 ton
B35: Taiwan | C35: Taichung | D35: ='Process - Intl'!AG30 -> 54.543252 | E35: ='Process - Intl'!AG59 -> 54.579345 | F35: ='Process - Intl'!AG88 -> 38.192819 | G35: ='Process - Intl'!AG117 -> 56.871294 | H35: ='Process - Intl'!AG146 -> 51.511383 | I35: Handy SR 15.000 ton
A37: Catatan:
A38: *Tripcharter Rate Estimates Clarksons SIW per 09/05/2025

Sheet Sheet1
A1: Perbandingan tarif sewa kapal/size kapal | B1: 0.2063
A2: 5000 | B2: =A2*B1 -> 1031.5
A3: 30000 | B3: 29.8
A5: TCE | B5: Bunker | C5: Port Charge
A7: OPEX
A8: Gaji
A9: Repairs/Maintenance
A10: Sparepart
A11: Asuransi
A12: Bunga
A13: Overhead
A14: Lube Oil
A15: Drydock
A16: Provision
A18: Depresiasi | B18: Clarkson
A19: =5500000/20/365 -> 753.42466

Sheet DatVal
A2: General Cargo | B2: Owned | C2: Waiting Loading | D2: 1 | E2: HSD
A3: Dry bulk | B3: Charter | C3: Loading | D3: 2 | E3: VLSFO
A4: LPG/C | C4: Sailing to PoD | D4: 3
C5: Waiting Discharge | D5: 4
C6: Discharge | D6: 5
C7: Sailing to PoL | D7: 6
C8: Ship Breakdown | D8: 7
C9: Waiting Instruction | D9: 8
D10: 9
D11: 10
C12: Ship Breakdown | D12: 11
D13: 12
D14: 13
D15: 14
D16: 15
D17: 16
D18: 17
D19: 18
D20: 19
D21: 20
D22: 21
D23: 22
D24: 23
... D31: 30
